<?xml version='1.0'?>

<robot name="robot" xmlns:xacro="http://www.ros.org/wiki/xacro">



  <xacro:include filename="$(find autobin_description)/urdf/autobin.gazebo" />
  <xacro:include filename="$(find autobin_description)/urdf/materials.xacro" />


  <link name='bin'>
    <inertial>
      <mass value="1.0"/>
      <origin xyz="0 0 0.05" rpy=" 0 0 0"/>
      <inertia
          ixx="0.166667" ixy="0" ixz="0"
          iyy="0.166667" iyz="0"
          izz="0.166667"
      />
    </inertial>


    <collision name='collision'>
      <origin xyz="0 0 0.05" rpy=" 0 0 0"/>
      <geometry>
        <mesh filename="package://autobin_description/meshes/bin.dae" scale="2 2 2"/>
      </geometry>
    </collision>

    <visual name='visual'>
      <origin xyz="0 0 0.05" rpy=" 0 0 0"/>
      <geometry>
        <mesh filename="package://autobin_description/meshes/bin.dae" scale="2 2 2"/>
      </geometry>
      <material name="grey"/>
    </visual>
    
    <collision name='caster_collision'>
      <origin xyz="-0.2 0 0.05" rpy=" 0 0 0"/>
      <geometry>
        <sphere radius="0.05"/>
      </geometry>
      <surface>
        <friction>
          <ode>
            <mu>0</mu>
            <mu2>0</mu2>
            <slip1>1.0</slip1>
            <slip2>1.0</slip2>
          </ode>
        </friction>
      </surface>
    </collision>

    <visual name='caster_visual'>
      <origin xyz="-0.2 0 0.05" rpy=" 0 0 0"/>
      <geometry>
        <sphere radius="0.05"/>
      </geometry>
    </visual>
  </link>


  <link name="left_wheel">
    <inertial>
      <origin xyz="0.1 0.1732 0.05" rpy="1.5708 0 0"/>
      <mass value="1"/>
      <inertia
        ixx="0.145833" ixy="0.0" ixz="0.0"
        iyy="0.145833" iyz="0.0"
        izz="0.125"/>
    </inertial>

    <collision name="collision">
      <!--origin xyz="0.1 0.1732 0.05" rpy="1.5708 0 0"/-->
      <geometry>
        <cylinder radius="0.05" length="0.1"/>
      </geometry>
    </collision>

    <visual name="visual">
      <!--origin xyz="0.1 0.1732 0.05" rpy="1.5708 0 0"/-->
      <geometry>
        <cylinder radius="0.05" length="0.1"/>
      </geometry>
    </visual>
  </link>

  <link name="right_wheel">
    <inertial>
      <origin xyz="0.1 -0.1732 0.05" rpy="1.5708 0 0"/>
      <mass value="1"/>
      <inertia
        ixx="0.145833" ixy="0.0" ixz="0.0"
        iyy="0.145833" iyz="0.0"
        izz="0.125"/>
    </inertial>

    <collision name="collision">
      <!--origin xyz="0.1 -0.1732 0.05" rpy="1.5708 0 0"/-->
      <geometry>
        <cylinder radius="0.05" length="0.1"/>
      </geometry>
    </collision>

    <visual name="visual">
      <!--origin xyz="0.1 -0.1732 0.05" rpy="1.5708 0 0"/-->
      <geometry>
        <cylinder radius="0.05" length="0.1"/>
      </geometry>
    </visual>
  </link>

  <joint type="continuous" name="left_wheel_hinge">
    <origin xyz="0.1 0.1732 0.05" rpy="1.5708 0 0"/>
    <parent link="bin"/>
    <child link="left_wheel"/>
    <axis xyz="0 1 0" rpy="0 0 0"/>
    <dynamics damping="0.0" friction="0.0"/>
  </joint>

  <joint type="continuous" name="right_wheel_hinge">
    <origin xyz="0.1 -0.1732 0.05" rpy="1.5708 0 0"/>
    <parent link="bin"/>
    <child link="right_wheel"/>
    <axis xyz="0 1 0" rpy="0 0 0"/>
    <dynamics damping="0.0" friction="0.0"/>
  </joint>

</robot>
